<?xml version="1.0"?>
<!-- =================================================================================== -->
<!-- |    This document was autogenerated by xacro from diablo_ASM.xacro               | -->
<!-- |    EDITING THIS FILE BY HAND IS NOT RECOMMENDED                                 | -->
<!-- =================================================================================== -->
<robot name="diablo_erc">
    <material name="black">
        <color rgba="0.2 0.2 0.2 1" />
    </material>

    <material name="yellow">
        <color rgba="1 0.95 0.6 1" />
    </material>

    <material name="gray">
        <color rgba="0.5 0.5 0.5 1" />
    </material>

    <material name="red">
        <color rgba="1 0 0 1" />
    </material>

    <link name="diablo_base_link">
        <inertial>
            <origin xyz="0.020214 1.4086E-08 0.0092665" rpy="0 0 0" />
            <mass value="5.621" />
            <inertia ixx="0.071628" ixy="-5.9879E-09" ixz="-0.00097471" iyy="0.16274"
                iyz="-1.6369E-08" izz="0.14673" />
        </inertial>
        <visual>
            <origin xyz="0 0 0" rpy="0 0 0" />
            <geometry>
                <mesh filename="../meshes/diablo_erc_base_link.STL" />
            </geometry>
            <material name="gray" />
        </visual>
        <collision>
            <origin xyz="0 0 0" rpy="0 0 0" />
            <geometry>
                <mesh filename="../meshes/diablo_base_link.STL" />
            </geometry>
        </collision>
    </link>

	<!-- base_head -->
	<joint name="base_head_joint" type="fixed">
		<origin rpy="0 0 0" xyz="0 0 0" />
		<parent link="diablo_base_link" />
		<child link="base_head_link" />
	</joint>

	<link name="base_head_link">
		<visual>
			<origin rpy="0 0 0" xyz="0 0 0" />
			<geometry>
				<mesh filename="../meshes/diablo_base_head.STL" />
			</geometry>
			<material name="yellow" />
		</visual>
	</link>

    <joint name="diablo_connection_joint" type="fixed">
        <origin xyz="0.0 0.0 -0.12" rpy="0 0 0" />
        <parent link="base_link" />
        <child link="diablo_base_link" />
    </joint>

    <!-- left_leg -->
    <joint name="left_fake_hip_joint" type="revolute">
        <origin rpy="1.5708 0.13433 -3.1416" xyz="0 0.18755 0" />
        <parent link="diablo_base_link" />
        <child link="left_fake_thigh_link" />
        <axis xyz="0 0 1" />
        <limit effort="27" lower="-1.57" upper="1.57" velocity="26" />
    </joint>

    <link name="left_fake_thigh_link">
        <inertial>
            <origin rpy="0 0 0" xyz="0 0 0" />
            <mass value="2.5" />
            <inertia ixx="0.006704" ixy="5.557e-09" ixz="-0.000131826" iyy="0.0069816"
                iyz="9.009e-10"
                izz="0.0069712" />
        </inertial>
        <visual>
            <origin rpy="0 0 0" xyz="0 0 0" />
            <geometry>
                <mesh filename="../meshes/left_motor_erc.STL" scale="1 1 1" />
            </geometry>
            <material name="gray" />
        </visual>
        <collision>
            <origin rpy="0 0 0" xyz="0 0 0" />
            <geometry>
                <mesh filename="../meshes/left_motor.STL" scale="1 1 1" />
            </geometry>
        </collision>
    </link>

    <joint name="left_fake_knee_joint" type="revolute">
        <origin rpy="0 0 -2.8729" xyz="0.14 0 0" />
        <parent link="left_fake_thigh_link" />
        <child link="left_fake_shank_link" />
        <axis xyz="0 0 1" />
        <limit effort="27" lower="-0.1" upper="2.9" velocity="26" />
    </joint>

    <link name="left_fake_shank_link">
        <inertial>
            <origin rpy="0 0 0" xyz="0 0 0" />
            <mass value="0.071103" />
            <inertia ixx="1.6657e-05" ixy="-5.5246e-06" ixz="3.9598e-14" iyy="0.00017966"
                iyz="-6.5493e-15" izz="0.00019328" />
        </inertial>
        <visual>
            <origin rpy="0 0 0" xyz="0 0 0" />
            <geometry>
                <mesh filename="../meshes/left_leg3.STL" scale="1 1 1" />
            </geometry>
            <material name="gray" />
        </visual>
        <collision>
            <origin rpy="0 0 0" xyz="0 0 0" />
            <geometry>
                <mesh filename="../meshes/left_leg3.STL" scale="1 1 1" />
            </geometry>
        </collision>
    </link>

    <joint name="left_wheel_joint" type="revolute">
        <origin rpy="0 0 0.13433" xyz="0.14 0 0.025" />
        <parent link="left_fake_shank_link" />
        <child link="left_wheel" />
        <axis xyz="0 0 1" />
        <limit effort="27" velocity="26" />
    </joint>

    <link name="left_wheel">
        <inertial>
            <origin rpy="0 0 0" xyz="0 0 0" />
            <mass value="2.9494" />
            <inertia ixx="0.0069338" ixy="2.8693e-09" ixz="4.6779e-09" iyy="0.006934"
                iyz="-5.0441e-11"
                izz="0.012567" />
        </inertial>
        <visual>
            <origin rpy="0 0 0" xyz="0 0 0" />
            <geometry>
                <mesh filename="../meshes/left_wheel.STL" scale="1 1 1" />
            </geometry>
            <material name="black" />
        </visual>
        <collision>
            <origin rpy="0 0 0" xyz="0 0 0" />
            <geometry>
                <mesh filename="../meshes/left_wheel.STL" scale="1 1 1" />
            </geometry>
        </collision>
    </link>

    <!-- right_leg -->
    <joint name="right_fake_hip_joint" type="revolute">
        <origin rpy="1.5708 0.13433 3.1416" xyz="0 -0.18755 0" />
        <parent link="diablo_base_link" />
        <child link="right_fake_thigh_link" />
        <axis xyz="0 0 1" />
        <limit effort="27" lower="-1.57" upper="1.57" velocity="26" />
    </joint>

    <link name="right_fake_thigh_link">
        <inertial>
            <origin rpy="0 0 0" xyz="0 0 0" />
            <mass value="2.5" />
            <inertia ixx="0.006704" ixy="5.557e-09" ixz="-0.000131826" iyy="0.0069816"
                iyz="9.009e-10"
                izz="0.0069712" />
        </inertial>
        <visual>
            <origin rpy="0 0 0" xyz="0 0 0" />
            <geometry>
                <mesh filename="../meshes/right_motor_erc.STL" scale="1 1 1" />
            </geometry>
            <material name="gray" />
        </visual>
        <collision>
            <origin rpy="0 0 0" xyz="0 0 0" />
            <geometry>
                <mesh filename="../meshes/right_motor.STL" scale="1 1 1" />
            </geometry>
        </collision>
    </link>

    <joint name="right_fake_knee_joint" type="revolute">
        <origin rpy="0 0 -2.8729" xyz="0.14 0 0" />
        <parent link="right_fake_thigh_link" />
        <child link="right_fake_shank_link" />
        <axis xyz="0 0 1" />
        <limit effort="27" lower="-0.1" upper="2.9" velocity="26" />
    </joint>

    <link name="right_fake_shank_link">
        <inertial>
            <origin rpy="0 0 0" xyz="0 0 0" />
            <mass value="0.071103" />
            <inertia ixx="1.6657e-05" ixy="-5.5246e-06" ixz="1.4852e-14" iyy="0.00017966"
                iyz="-6.5194e-14" izz="0.00019328" />
        </inertial>
        <visual>
            <origin rpy="0 0 0" xyz="0 0 0" />
            <geometry>
                <mesh filename="../meshes/right_leg3.STL" scale="1 1 1" />
            </geometry>
            <material name="gray" />
        </visual>
        <collision>
            <origin rpy="0 0 0" xyz="0 0 0" />
            <geometry>
                <mesh filename="../meshes/right_leg3.STL" scale="1 1 1" />
            </geometry>
        </collision>
    </link>

    <joint name="right_wheel_joint" type="revolute">
        <origin rpy="0 0 0.13433" xyz="0.14 0 -0.025" />
        <parent link="right_fake_shank_link" />
        <child link="right_wheel" />
        <axis xyz="0 0 1" />
        <limit effort="27" velocity="26" />
    </joint>

    <link name="right_wheel">
        <inertial>
            <origin rpy="0 0 0" xyz="0 0 0" />
            <mass value="2.9494" />
            <inertia ixx="0.0069338" ixy="2.8693e-09" ixz="4.6779e-09" iyy="0.006934"
                iyz="-5.0441e-11"
                izz="0.012567" />
        </inertial>
        <visual>
            <origin rpy="0 0 0" xyz="0 0 0" />
            <geometry>
                <mesh filename="../meshes/right_wheel.STL" scale="1 1 1" />
            </geometry>
            <material name="black" />
        </visual>
        <collision>
            <origin rpy="0 0 0" xyz="0 0 0" />
            <geometry>
                <mesh filename="../meshes/right_wheel.STL" scale="1 1 1" />
            </geometry>
        </collision>
    </link>

    <link name="base_link">
        <inertial>
            <origin xyz="-0.000202 0.000000 0.165441" rpy="0 0 0" />
            <mass value="1.2548" />
            <inertia
                ixx="0.016818" ixy="0.000012" ixz="-0.000009"
                iyy="0.014554" iyz="0.000000" izz="0.003778" />
        </inertial>
        <visual>
            <origin xyz="0 0 0" rpy="0 0 0" />
            <geometry>
                <mesh filename="../base/base_link.STL" />
            </geometry>
            <material name="black" />
        </visual>
        <collision>
            <origin xyz="0 0 0" rpy="0 0 0" />
            <geometry>
                <mesh filename="../base/base_link_col.STL" />
            </geometry>
        </collision>
    </link>

    <link
        name="l_sho_pitch_link">
        <inertial>
            <origin xyz="0.000663 0.027711 -0.000035" rpy="0 0 0" />
            <mass value="0.089" />
            <inertia ixx="0.000024" ixy="0.000000" ixz="0.000000"
                iyy="0.000015" iyz="0.000000" izz="0.000027" />
        </inertial>
        <visual>
            <origin xyz="0 0 0" rpy="0 0 0" />
            <geometry>
                <mesh filename="../l_sho_pitch/l_sho_pitch.STL" />
            </geometry>
            <material name="gray" />
        </visual>
        <collision>
            <origin xyz="0 0 0" rpy="0 0 0" />
            <geometry>
                <mesh filename="../l_sho_pitch/l_sho_pitch_col.STL" />
            </geometry>
        </collision>
    </link>

    <joint name="l_sho_pitch" type="revolute">
        <origin xyz="-0.0107 0.0950 0.2622" rpy="0 0 0" />
        <parent link="base_link" />
        <child link="l_sho_pitch_link" />
        <axis xyz="0 1 0" />
        <limit lower="-3.14" upper="1.309" effort="1.0" velocity="4.82" />
    </joint>

    <link name="l_sho_roll_link">
        <inertial>
            <origin xyz="-0.018978 0.000432 -0.112916" rpy="0 0 0" />
            <mass value="0.115" />
            <inertia ixx="0.000200" ixy="0.000000" ixz="0.000000"
                iyy="0.000201" iyz="-0.000001" izz="0.000020" />
        </inertial>
        <visual>
            <origin xyz="0 0 0" rpy="0 0 0" />
            <geometry>
                <mesh filename="../l_sho_roll/l_sho_roll.STL" />
            </geometry>
            <material name="gray" />
        </visual>
        <collision>
            <origin xyz="0 0 0" rpy="0 0 0" />
            <geometry>
                <mesh filename="../l_sho_roll/l_sho_roll_col.STL" />
            </geometry>
        </collision>
    </link>

    <joint name="l_sho_roll" type="revolute">
        <origin xyz="0.0187 0.0405 0.0000" rpy="0 0 0" />
        <parent link="l_sho_pitch_link" />
        <child link="l_sho_roll_link" />
        <axis xyz="1 0 0" />
        <limit lower="-0.22" upper="3.14" effort="1.0" velocity="4.82" />
    </joint>

    <link name="l_el_link">
        <inertial>
            <origin xyz="-0.000009 -0.019028 -0.053118" rpy="0 0 0" />
            <mass value="0.026000" />
            <inertia ixx="0.000020" ixy="0.000000" ixz="0.000000"
                iyy="0.000018" iyz="0.000000" izz="0.000004" />
        </inertial>
        <visual>
            <origin xyz="0 0 0" rpy="0 0 0" />
            <geometry>
                <mesh filename="../l_el/l_el.STL" />
            </geometry>
            <material name="gray" />
        </visual>
        <collision>
            <origin xyz="0 0 0" rpy="0 0 0" />
            <geometry>
                <mesh filename="../l_el/l_el_col.STL" />
            </geometry>
        </collision>
    </link>

    <joint name="l_el" type="revolute">
        <origin xyz="-0.0190 0.0194 -0.1505" rpy="0 0 0" />
        <parent link="l_sho_roll_link" />
        <child link="l_el_link" />
        <axis xyz="0 1 0" />
        <limit lower="-1.83" upper="1.83" effort="1.0" velocity="4.82" />
    </joint>

    <link name="l_wrist_link">
        <inertial>
            <origin xyz="-0.000435 0.003217 -0.043779" rpy="0 0 0" />
            <mass value="0.21616" />
            <inertia ixx="0.000183" ixy="0.000000" ixz="0.000000"
                iyy="0.000191" iyz="-0.000015" izz="0.000104" />
        </inertial>
        <visual>
            <origin xyz="0 0 0" rpy="0 0 0" />
            <geometry>
                <mesh filename="../l_wrist/l_wrist.STL" />
            </geometry>
            <material name="black" />
        </visual>
        <collision>
            <origin xyz="0 0 0" rpy="0 0 0" />
            <geometry>
                <mesh filename="../l_wrist/l_wrist.STL" />
            </geometry>
        </collision>
    </link>

    <joint name="l_wrist" type="revolute">
        <origin xyz="0 -0.019 -0.0910" rpy="0 0 0" />
        <parent link="l_el_link" />
        <child link="l_wrist_link" />
        <axis xyz="0 0 1" />
        <limit lower="-1.57" upper="1.57" effort="0.57" velocity="5.24" />
    </joint>

    <link name="head_pan_link">
        <inertial>
            <origin xyz="0.012229 -0.000618 0.019874" rpy="0 0 0" />
            <mass value="0.0982" />
            <inertia ixx=" 0.000020" ixy=" 0.000000" ixz="0.000000"
                iyy="0.000027" iyz="-0.000001" izz="0.000028" />
        </inertial>
        <visual>
            <origin xyz="0 0 0" rpy="0 0 0" />
            <geometry>
                <mesh filename="../head_pan/head_pan_link.STL" />
            </geometry>
            <material name="gray" />
        </visual>
        <collision>
            <origin xyz="0 0 0" rpy="0 0 0" />
            <geometry>
                <mesh filename="../head_pan/head_pan_link_col.STL" />
            </geometry>
        </collision>
    </link>

    <joint name="head_pan" type="revolute">
        <origin xyz="-0.012 0 0.297" rpy="0 0 0" />
        <parent link="base_link" />
        <child link="head_pan_link" />
        <axis xyz="0 0 1" />
        <limit lower="-3.14" upper="3.14" effort="0.28" velocity="5.97" />
    </joint>

    <link name="head_tilt_link">
		<inertial>
			<origin xyz="0.010888 -0.014125 0.052310" rpy="0 0 0" />
			<mass value="0.187" />
			<inertia ixx="0.000127" ixy="-0.000002" ixz="0.000025"
				iyy="0.000104" iyz="0.000001" izz="0.000129" />
		</inertial>
		<visual>
			<origin xyz="0 0 0" rpy="0 0 0" />
			<geometry>
				<mesh filename="../head_tilt/head_tilt_link_v1.STL" />
			</geometry>
			<material name="gray" />
		</visual>
		<collision>
			<origin xyz="0 0 0" rpy="0 0 0" />
			<geometry>
				<mesh filename="../head_tilt/head_tilt_link_erc.STL" />
			</geometry>
		</collision>
	</link>

    <joint name="head_tilt" type="revolute">
        <origin xyz="0.0249 0.0150 0.0208" rpy="0 0 0" />
        <parent link="head_pan_link" />
        <child link="head_tilt_link" />
        <axis xyz="0 1 0" />
        <limit lower="-0.61087" upper="0.61087" effort="0.28" velocity="5.97" />
    </joint>

    <joint name="eye_joint" type="fixed">
		<origin xyz="0 0 0" rpy="0 0 0" />
		<parent link="head_tilt_link" />
		<child link="eye_link" />
	</joint>

	<link name="eye_link">
		<visual>
			<origin xyz="0 0 0" rpy="0 0 0" />
			<geometry>
				<mesh filename="../head_tilt/eye_cover_link.STL" />
			</geometry>
			<material name="yellow" />
		</visual>
	</link>

    <link name="r_sho_pitch_link">
        <inertial>
            <origin xyz="0.000663 -0.027711 0.000035" rpy="0 0 0" />
            <mass value="0.089" />
            <inertia ixx="0.000024" ixy="0.000000" ixz="0.000000"
                iyy="0.000015" iyz="0.000000" izz="0.000027" />
        </inertial>
        <visual>
            <origin xyz="0 0 0" rpy="0 0 0" />
            <geometry>
                <mesh filename="../r_sho_pitch/r_sho_pitch.STL" />
            </geometry>
            <material name="gray" />
        </visual>
        <collision>
            <origin xyz="0 0 0" rpy="0 0 3.14" />
            <geometry>
                <mesh filename="../l_sho_pitch/l_sho_pitch_col.STL" />
            </geometry>
        </collision>
    </link>

    <joint name="r_sho_pitch" type="revolute">
        <origin xyz="-0.0107 -0.0950 0.2622" rpy="0 0 0" />
        <parent link="base_link" />
        <child link="r_sho_pitch_link" />
        <axis xyz="0 1 0" />
        <limit lower="-3.14" upper="3.14" effort="1.0" velocity="4.82" />
    </joint>

    <link name="r_sho_roll_link">
        <inertial>
            <origin xyz="-0.018978 0.000432 -0.112916" rpy="0 0 0" />
            <mass value="0.115" />
            <inertia ixx="0.000200" ixy="0.000000" ixz="0.000000"
                iyy="0.000201" iyz="-0.000001" izz="0.000020" />
        </inertial>
        <visual>
            <origin xyz="0 0 0" rpy="0 0 0" />
            <geometry>
                <mesh filename="../r_sho_roll/r_sho_roll.STL" />
            </geometry>
            <material name="gray" />
        </visual>
        <collision>
            <origin xyz="0 0 0" rpy="0 0 0" />
            <geometry>
                <mesh filename="../l_sho_roll/l_sho_roll_col.STL" />
            </geometry>
        </collision>
    </link>

    <joint name="r_sho_roll" type="revolute">
        <origin xyz="0.0187 -0.0405 0.0000" rpy="0 0 0" />
        <parent link="r_sho_pitch_link" />
        <child link="r_sho_roll_link" />
        <axis xyz="1 0 0" />
        <limit lower="-3.14" upper="0.22" effort="1.0" velocity="4.82" />
    </joint>

    <link name="r_el_link">
        <inertial>
            <origin xyz="0.000018 0.019027 -0.053118" rpy="0 0 0" />
            <mass value="0.026000" />
            <inertia ixx="0.000020" ixy="0.000000" ixz="0.000000"
                iyy="0.000018" iyz="0.000000" izz="0.000004" />
        </inertial>
        <visual>
            <origin xyz="0 0 0" rpy="0 0 0" />
            <geometry>
                <mesh filename="../r_el/r_el.STL" />
            </geometry>
            <material name="gray" />
        </visual>
        <collision>
            <origin xyz="0 0 0" rpy="0 0 3.14" />
            <geometry>
                <mesh filename="../l_el/l_el_col.STL" />
            </geometry>
        </collision>
    </link>

    <joint name="r_el" type="revolute">
        <origin xyz="-0.01900 -0.0194 -0.1505" rpy="0 0 0" />
        <parent link="r_sho_roll_link" />
        <child link="r_el_link" />
        <axis xyz="0 1 0" />
        <limit lower="-2" upper="0" effort="1.0" velocity="4.82" />
    </joint>

    <link name="r_wrist_link">
        <inertial>
            <origin xyz="-0.000466 -0.003178 -0.043764" rpy="0 0 0" />
            <mass value="0.21616" />
            <inertia ixx="0.000183" ixy="0.000000" ixz="0.000000"
                iyy="0.000191" iyz="0.000015" izz="0.000104" />
        </inertial>
        <visual>
            <origin  xyz="0 0 0" rpy="0 0 0" />
            <geometry>
                <mesh filename="../r_wrist/r_wrist.STL" />
            </geometry>
            <material name="black" />
        </visual>
        <collision>
            <origin xyz="0 0 0" rpy="0 0 0" />
            <geometry>
                <mesh filename="../r_wrist/r_wrist.STL" />
            </geometry>
        </collision>
    </link>

    <joint name="r_wrist" type="revolute">
        <origin xyz="0 0.0190 -0.0910" rpy="0 0 0" />
        <parent link="r_el_link" />
        <child link="r_wrist_link" />
        <axis xyz="0 0 1" />
        <limit lower="-1.57" upper="1.57" effort="0.57" velocity="5.24" />
    </joint>

    <link name="l_index_base_link">
        <inertial>
            <origin xyz="0.00013253 0.00117799 -0.012500" rpy="0 0 0" />
            <mass value="0.00372" />
            <inertia ixx="0.00000027" ixy="0.00000000" ixz="0.00000000"
                iyy="0.00000032" iyz="0.00000000" izz="0.00000014" />
        </inertial>
        <visual>
            <origin xyz="0 0 0" rpy="0 0 0" />
            <geometry>
                <mesh filename="../finger/base/finger_base.STL" />
            </geometry>
            <material name="black" />
        </visual>
        <collision>
            <origin xyz="0 0 0.003" rpy="0 0 0" />
            <geometry>
                <mesh filename="../finger/base/finger_base.STL" />
            </geometry>
        </collision>
    </link>

    <joint name="l_index_base" type="revolute">
        <origin xyz="-0.0197 0.012 -0.0910" rpy="0.2 0.15 0" />
        <parent link="l_wrist_link" />
        <child link="l_index_base_link" />
        <axis xyz="-1 0 0" />
        <limit lower="0" upper="0.9" effort="0.20" velocity="2.62" />
    </joint>

    <link name="l_index_middle_link">
        <inertial>
            <origin xyz="-0.00010821 0.00117022 -0.01260225" rpy="0 0 0" />
            <mass value="0.00372" />
            <inertia ixx="0.00000028" ixy="0.00000000" ixz="0.00000000"
                iyy="0.00000038" iyz="0.00000000" izz="0.00000015" />
        </inertial>
        <visual>
            <origin xyz="0 0 0" rpy="0 0 0" />
            <geometry>
                <mesh filename="../finger/middle/finger_middle.STL" />
            </geometry>
            <material name="black" />
        </visual>
        <collision>
            <origin xyz="0 0 0.003" rpy="0 0 0" />
            <geometry>
                <mesh filename="../finger/middle/finger_middle.STL" />
            </geometry>
        </collision>
    </link>

    <joint name="l_index_middle" type="revolute">
        <origin xyz="0.0 -0.003 -0.014" rpy="0 0 0" />
        <parent link="l_index_base_link" />
        <child link="l_index_middle_link" />
        <axis xyz="-1 0 0" />
        <mimic joint="l_index_base" multiplier="1.0" offset="0.0" />
        <limit lower="0" upper="0.9" effort="0.2" velocity="0.4" />
    </joint>

    <link
        name="l_index_tip_link">
        <inertial>
            <origin xyz="0.00007447 0.00115239 -0.01200000" rpy="0 0 0" />
            <mass value="0.00372" />
            <inertia ixx="0.00000026" ixy="0.00000000" ixz="0.00000000"
                iyy="0.00000030" iyz="0.00000000" izz="0.00000014" />
        </inertial>
        <visual>
            <origin xyz="0 0 0" rpy="0 0 0" />
            <geometry>
                <mesh filename="../finger/tip/finger_tip.STL" />
            </geometry>
            <material name="black" />
        </visual>
        <collision>
            <origin xyz="0 0 0.003" rpy="0 0 0" />
            <geometry>
                <mesh filename="../finger/tip/finger_tip.STL" />
            </geometry>
        </collision>
    </link>

    <joint name="l_index_tip" type="revolute">
        <origin xyz="0.0 -0.003 -0.014" rpy="0 0 0" />
        <parent link="l_index_middle_link" />
        <child link="l_index_tip_link" />
        <axis xyz="-1 0 0" />
        <mimic joint="l_index_base" multiplier="1.0" offset="0.0" />
        <limit lower="0" upper="0.9" effort="0.2" velocity="0.4" />
    </joint>

    <link name="l_mid_base_link">
        <inertial>
            <origin xyz="0.00013253 0.00117799 -0.012500" rpy="0 0 0" />
            <mass value="0.00372" />
            <inertia ixx="0.00000027" ixy="0.00000000" ixz="0.00000000"
                iyy="0.00000032" iyz="0.00000000" izz="0.00000014" />
        </inertial>
        <visual>
            <origin xyz="0 0 0" rpy="0 0 0" />
            <geometry>
                <mesh filename="../finger/base/finger_base.STL" />
            </geometry>
            <material name="black" />
        </visual>
        <collision>
            <origin xyz="0 0 0" rpy="0 0 0" />
            <geometry>
                <mesh filename="../finger/base/finger_base.STL" />
            </geometry>
        </collision>
    </link>

    <joint name="l_mid_base" type="revolute">
        <origin xyz="0.0197 0.012 -0.0910" rpy="0.2 0.0 0" />
        <parent link="l_wrist_link" />
        <child link="l_mid_base_link" />
        <axis xyz="-1 0 0" />
        <limit lower="0" upper="0.9" effort="0.20" velocity="2.62" />
    </joint>

    <link name="l_mid_middle_link">
        <inertial>
            <origin xyz="-0.00010821 0.00117022 -0.01260225" rpy="0 0 0" />
            <mass value="0.00372" />
            <inertia ixx="0.00000028" ixy="0.00000000" ixz="0.00000000"
                iyy="0.00000038" iyz="0.00000000" izz="0.00000015" />
        </inertial>
        <visual>
            <origin xyz="0 0 0" rpy="0 0 0" />
            <geometry>
                <mesh filename="../finger/middle/finger_middle.STL" />
            </geometry>
            <material name="black" />
        </visual>
        <collision>
            <origin xyz="0 0 0.003" rpy="0 0 0" />
            <geometry>
                <mesh filename="../finger/middle/finger_middle.STL" />
            </geometry>
        </collision>
    </link>

    <joint name="l_mid_middle" type="revolute">
        <origin xyz="0.0 -0.003 -0.014" rpy="0 0 0" />
        <parent link="l_mid_base_link" />
        <child link="l_mid_middle_link" />
        <axis xyz="-1 0 0" />
        <mimic joint="l_mid_base" multiplier="1.0" offset="0.0" />
        <limit lower="0" upper="0.9" effort="0.2" velocity="0.4" />
    </joint>

    <link name="l_mid_tip_link">
        <inertial>
            <origin xyz="0.00007447 0.00115239 -0.01200000" rpy="0 0 0" />
            <mass value="0.00372" />
            <inertia ixx="0.00000026" ixy="0.00000000" ixz="0.00000000"
                iyy="0.00000030" iyz="0.00000000" izz="0.00000014" />
        </inertial>
        <visual>
            <origin xyz="0 0 0" rpy="0 0 0" />
            <geometry>
                <mesh filename="../finger/tip/finger_tip.STL" />
            </geometry>
            <material name="black" />
        </visual>
        <collision>
            <origin xyz="0 0 0.003" rpy="0 0 0" />
            <geometry>
                <mesh filename="../finger/tip/finger_tip.STL" />
            </geometry>
        </collision>
    </link>

    <joint name="l_mid_tip" type="revolute">
        <origin xyz="0.0 -0.003 -0.014" rpy="0 0 0" />
        <parent link="l_mid_middle_link" />
        <child link="l_mid_tip_link" />
        <axis xyz="-1 0 0" />
        <mimic joint="l_mid_base" multiplier="1.0" offset="0.0" />
        <limit lower="0" upper="0.9" effort="0.2" velocity="0.4" />
    </joint>

    <link name="l_thumb_base_link">
        <inertial>
            <origin xyz="0.00013253 0.00117799 -0.012500" rpy="0 0 0" />
            <mass value="0.00372" />
            <inertia ixx="0.00000027" ixy="0.00000000" ixz="0.00000000"
                iyy="0.00000032" iyz="0.00000000" izz="0.00000014" />
        </inertial>
        <visual>
            <origin xyz="0 0 0" rpy="0 0 0" />
            <geometry>
                <mesh filename="../finger/base/finger_base.STL" />
            </geometry>
            <material name="black" />
        </visual>
        <collision>
            <origin xyz="0 0 0.003" rpy="0 0 0" />
            <geometry>
                <mesh filename="../finger/base/finger_base.STL" />
            </geometry>
        </collision>
    </link>

    <joint name="l_thumb_base" type="revolute">
        <origin xyz="0.000 -0.022 -0.077" rpy="1 0.15 3.14" />
        <parent link="l_wrist_link" />
        <child link="l_thumb_base_link" />
        <axis xyz="-1 0 0" />
        <limit lower="0" upper="0.9" effort="0.20" velocity="2.62" />
    </joint>

    <link name="l_thumb_middle_link">
        <inertial>
            <origin xyz="-0.00010821 0.00117022 -0.01260225" rpy="0 0 0" />
            <mass value="0.00372" />
            <inertia ixx="0.00000028" ixy="0.00000000" ixz="0.00000000"
                iyy="0.00000038" iyz="0.00000000" izz="0.00000015" />
        </inertial>
        <visual>
            <origin xyz="0 0 0" rpy="0 0 0" />
            <geometry>
                <mesh filename="../finger/middle/finger_middle.STL" />
            </geometry>
            <material name="black" />
        </visual>
        <collision>
            <origin xyz="0 0 0.003" rpy="0 0 0" />
            <geometry>
                <mesh filename="../finger/middle/finger_middle.STL" />
            </geometry>
        </collision>
    </link>

    <joint
        name="l_thumb_middle"
        type="revolute">
        <origin
            xyz="0.0 -0.003 -0.014"
            rpy="0 0 0" />
        <parent
            link="l_thumb_base_link" />
        <child
            link="l_thumb_middle_link" />
        <mimic joint="l_thumb_base" multiplier="1.0" offset="0.0" />
        <axis
            xyz="-1 0 0" />
        <limit
            lower="0"
            upper="0.9"
            effort="0.2"
            velocity="0.4" />
    </joint>
    
    <link
        name="l_thumb_tip_link">
        <inertial>
            <origin
                xyz="0.00007447 0.00115239 -0.01200000"
                rpy="0 0 0" />
            <mass
                value="0.00372" />
            <inertia
                ixx="0.00000026"
                ixy="0.00000000"
                ixz="0.00000000"
                iyy="0.00000030"
                iyz="0.00000000"
                izz="0.00000014" />
        </inertial>
        <visual>
            <origin
                xyz="0 0 0"
                rpy="0 0 0" />
            <geometry>
                <mesh
                    filename="../finger/tip/finger_tip.STL" />
            </geometry>
            <material name="black" />
        </visual>
        <collision>
            <origin
                xyz="0 0 0.003"
                rpy="0 0 0" />
            <geometry>
                <mesh
                    filename="../finger/tip/finger_tip.STL" />
            </geometry>
        </collision>
    </link>

    <joint
        name="l_thumb_tip"
        type="revolute">
        <origin
            xyz="0.0 -0.003 -0.014"
            rpy="0 0 0" />
        <parent
            link="l_thumb_middle_link" />
        <child
            link="l_thumb_tip_link" />
        <axis
            xyz="-1 0 0" />
        <mimic joint="l_thumb_base" multiplier="1.0" offset="0.0" />
        <limit
            lower="0"
            upper="0.9"
            effort="0.2"
            velocity="0.4" />
    </joint>

    <link
        name="r_index_base_link">
        <inertial>
            <origin
                xyz="0.00013253 0.00117799 -0.012500"
                rpy="0 0 0" />
            <mass
                value="0.00372" />
            <inertia
                ixx="0.00000027"
                ixy="0.00000000"
                ixz="0.00000000"
                iyy="0.00000032"
                iyz="0.00000000"
                izz="0.00000014" />
        </inertial>
        <visual>
            <origin
                xyz="0 0 0"
                rpy="0 0 0" />
            <geometry>
                <mesh
                    filename="../finger/base/finger_base.STL" />
            </geometry>
            <material name="black" />
        </visual>
        <collision>
            <origin
                xyz="0 0 0.003"
                rpy="0 0 0" />
            <geometry>
                <mesh
                    filename="../finger/base/finger_base.STL" />
            </geometry>
        </collision>
    </link>

    <joint name="r_index_base" type="revolute">
        <origin xyz="-0.0197 -0.008 -0.0910" rpy="0.2 -0.15 3.14" />
        <parent link="r_wrist_link" />
        <child link="r_index_base_link" />
        <axis xyz="-1 0 0" />
        <limit lower="0" upper="0.9" effort="0.20" velocity="2.62" />
    </joint>
    
    <link name="r_index_middle_link">
        <inertial>
            <origin xyz="-0.00010821 0.00117022 -0.01260225" rpy="0 0 0" />
            <mass value="0.00372" />
            <inertia ixx="0.00000028" ixy="0.00000000" ixz="0.00000000"
                iyy="0.00000038" iyz="0.00000000" izz="0.00000015" />
        </inertial>
        <visual>
            <origin xyz="0 0 0" rpy="0 0 0" />
            <geometry>
                <mesh filename="../finger/middle/finger_middle.STL" />
            </geometry>
            <material name="black" />
        </visual>
        <collision>
            <origin xyz="0 0 0.003" rpy="0 0 0" />
            <geometry>
                <mesh filename="../finger/middle/finger_middle.STL" />
            </geometry>
        </collision>
    </link>

    <joint name="r_index_middle" type="revolute">
        <origin xyz="0.0 -0.003 -0.014" rpy="0 0 0" />
        <parent link="r_index_base_link" />
        <child link="r_index_middle_link" />
        <axis xyz="-1 0 0" />
        <mimic joint="r_index_base" multiplier="1.0" offset="0.0" />
        <limit lower="0" upper="0.9" effort="0.2" velocity="0.4" />
    </joint>

    <link name="r_index_tip_link">
        <inertial>
            <origin xyz="0.00007447 0.00115239 -0.01200000" rpy="0 0 0" />
            <mass value="0.00372" />
            <inertia ixx="0.00000026" ixy="0.00000000" ixz="0.00000000"
                iyy="0.00000030" iyz="0.00000000" izz="0.00000014" />
        </inertial>
        <visual>
            <origin xyz="0 0 0" rpy="0 0 0" />
            <geometry>
                <mesh filename="../finger/tip/finger_tip.STL" />
            </geometry>
            <material name="black" />
        </visual>
        <collision>
            <origin xyz="0 0 0.003" rpy="0 0 0" />
            <geometry>
                <mesh filename="../finger/tip/finger_tip.STL" />
            </geometry>
        </collision>
    </link>

    <joint name="r_index_tip" type="revolute">
        <origin xyz="0.0 -0.003 -0.014" rpy="0 0 0" />
        <parent link="r_index_middle_link" />
        <child link="r_index_tip_link" />
        <axis xyz="-1 0 0" />
        <mimic joint="r_index_base" multiplier="1.0" offset="0.0" />
        <limit lower="0" upper="0.9" effort="0.2" velocity="0.4" />
    </joint>

    <link name="r_mid_base_link">
        <inertial>
            <origin xyz="0.00013253 0.00117799 -0.012500" rpy="0 0 0" />
            <mass value="0.00372" />
            <inertia ixx="0.00000027" ixy="0.00000000" ixz="0.00000000"
                iyy="0.00000032" iyz="0.00000000" izz="0.00000014" />
        </inertial>
        <visual>
            <origin xyz="0 0 0" rpy="0 0 0" />
            <geometry>
                <mesh filename="../finger/base/finger_base.STL" />
            </geometry>
            <material name="black" />
        </visual>
        <collision>
            <origin xyz="0 0 0" rpy="0 0 0" />
            <geometry>
                <mesh filename="../finger/base/finger_base.STL" />
            </geometry>
        </collision>
    </link>

    <joint name="r_mid_base" type="revolute">
        <origin xyz="0.0197 -0.012 -0.0910" rpy="0.2 0.0 3.14" />
        <parent link="r_wrist_link" />
        <child link="r_mid_base_link" />
        <axis xyz="-1 0 0" />
        <limit lower="0" upper="0.9" effort="0.20" velocity="2.62" />
    </joint>

    <link name="r_mid_middle_link">
        <inertial>
            <origin xyz="-0.00010821 0.00117022 -0.01260225" rpy="0 0 0" />
            <mass value="0.00372" />
            <inertia ixx="0.00000028" ixy="0.00000000" ixz="0.00000000"
                iyy="0.00000038" iyz="0.00000000" izz="0.00000015" />
        </inertial>
        <visual>
            <origin xyz="0 0 0" rpy="0 0 0" />
            <geometry>
                <mesh filename="../finger/middle/finger_middle.STL" />
            </geometry>
            <material name="black" />
        </visual>
        <collision>
            <origin xyz="0 0 0.003" rpy="0 0 0" />
            <geometry>
                <mesh filename="../finger/middle/finger_middle.STL" />
            </geometry>
        </collision>
    </link>

    <joint name="r_mid_middle" type="revolute">
        <origin xyz="0.0 -0.003 -0.014" rpy="0 0 0" />
        <parent link="r_mid_base_link" />
        <child link="r_mid_middle_link" />
        <axis xyz="-1 0 0" />
        <mimic joint="r_mid_base" multiplier="1.0" offset="0.0" />
        <limit lower="0" upper="0.9" effort="0.2" velocity="0.4" />
    </joint>

    <link name="r_mid_tip_link">
        <inertial>
            <origin xyz="0.00007447 0.00115239 -0.01200000" rpy="0 0 0" />
            <mass value="0.00372" />
            <inertia ixx="0.00000026" ixy="0.00000000" ixz="0.00000000"
                iyy="0.00000030" iyz="0.00000000" izz="0.00000014" />
        </inertial>
        <visual>
            <origin xyz="0 0 0" rpy="0 0 0" />
            <geometry>
                <mesh filename="../finger/tip/finger_tip.STL" />
            </geometry>
            <material name="black" />
        </visual>
        <collision>
            <origin
                xyz="0 0 0.003"
                rpy="0 0 0" />
            <geometry>
                <mesh filename="../finger/tip/finger_tip.STL" />
            </geometry>
        </collision>
    </link>

    <joint name="r_mid_tip" type="revolute">
        <origin xyz="0.0 -0.003 -0.014" rpy="0 0 0" />
        <parent link="r_mid_middle_link" />
        <child link="r_mid_tip_link" />
        <axis xyz="-1 0 0" />
        <mimic joint="r_mid_base" multiplier="1.0" offset="0.0" />
        <limit lower="0" upper="0.9" effort="0.2" velocity="0.4" />
    </joint>

    <link name="r_thumb_base_link">
        <inertial>
            <origin xyz="0.00013253 0.00117799 -0.012500" rpy="0 0 0" />
            <mass value="0.00372" />
            <inertia ixx="0.00000027" ixy="0.00000000" ixz="0.00000000"
                iyy="0.00000032" iyz="0.00000000" izz="0.00000014" />
        </inertial>
        <visual>
            <origin xyz="0 0 0" rpy="0 0 0" />
            <geometry>
                <mesh
                    filename="../finger/base/finger_base.STL" />
            </geometry>
            <material name="black" />
        </visual>
        <collision>
            <origin xyz="0 0 0.003" rpy="0 0 0" />
            <geometry>
                <mesh filename="../finger/base/finger_base.STL" />
            </geometry>
        </collision>
    </link>

    <joint name="r_thumb_base" type="revolute">
        <origin xyz="0.005 0.022 -0.077" rpy="1 0.15 0" />
        <parent link="r_wrist_link" />
        <child link="r_thumb_base_link" />
        <axis xyz="-1 0 0" />
        <limit lower="0" upper="0.9" effort="0.20" velocity="2.62" />
    </joint>

    <link name="r_thumb_middle_link">
        <inertial>
            <origin xyz="-0.00010821 0.00117022 -0.01260225" rpy="0 0 0" />
            <mass value="0.00372" />
            <inertia ixx="0.00000028" ixy="0.00000000" ixz="0.00000000"
                iyy="0.00000038" iyz="0.00000000" izz="0.00000015" />
        </inertial>
        <visual>
            <origin xyz="0 0 0" rpy="0 0 0" />
            <geometry>
                <mesh filename="../finger/middle/finger_middle.STL" />
            </geometry>
            <material name="black" />
        </visual>
        <collision>
            <origin xyz="0 0 0.003" rpy="0 0 0" />
            <geometry>
                <mesh filename="../finger/middle/finger_middle.STL" />
            </geometry>
        </collision>
    </link>
    
    <joint name="r_thumb_middle" type="revolute">
        <origin xyz="0.0 -0.003 -0.014" rpy="0 0 0" />
        <parent link="r_thumb_base_link" />
        <child link="r_thumb_middle_link" />
        <axis xyz="-1 0 0" />
        <mimic joint="r_thumb_base" multiplier="1.0" offset="0.0" />
        <limit lower="0" upper="0.9" effort="0.2" velocity="0.4" />
    </joint>

    <link name="r_thumb_tip_link">
        <inertial>
            <origin xyz="0.00007447 0.00115239 -0.01200000" rpy="0 0 0" />
            <mass value="0.00372" />
            <inertia ixx="0.00000026" ixy="0.00000000" ixz="0.00000000"
                iyy="0.00000030" iyz="0.00000000" izz="0.00000014" />
        </inertial>
        <visual>
            <origin xyz="0 0 0" rpy="0 0 0" />
            <geometry>
                <mesh filename="../finger/tip/finger_tip.STL" />
            </geometry>
            <material name="black" />
        </visual>
        <collision>
            <origin xyz="0 0 0.003" rpy="0 0 0" />
            <geometry>
                <mesh filename="../finger/tip/finger_tip.STL" />
            </geometry>
        </collision>
    </link>

    <joint name="r_thumb_tip" type="revolute">
        <origin xyz="0.0 -0.003 -0.014" rpy="0 0 0" />
        <parent link="r_thumb_middle_link" />
        <child link="r_thumb_tip_link" />
        <axis xyz="-1 0 0" />
        <mimic joint="r_thumb_base" multiplier="1.0" offset="0.0" />
        <limit lower="0" upper="0.9" effort="0.2" velocity="0.4" />
    </joint>

    <joint name="panda_grip_vis_joint" type="fixed">
        <parent link="r_wrist_link" />
        <child link="panda_grip_site" />
        <origin rpy="0 0 0" xyz="0.0 0.01 -0.1" />
    </joint>

    <link name="panda_grip_site">
        <visual>
            <geometry>
                <sphere radius="0.005" />
            </geometry>
            <material name="Vis" />
        </visual>
    </link>

</robot>
